<robot name = "robot">
    <link name="Torso">
        <inertial>
            <origin xyz="0 0 0.6147810551789473" rpy="0 0 0"/>
            <mass value="1" />
            <inertia ixx="100" ixy="0" ixz="0" iyy="100" iyz="0" izz="100" />
        </inertial>
        <visual>
            <origin xyz="0 0 0.6147810551789473" rpy="0 0 0"/>
            <geometry>
                <box size="0.7894706267661382 0.43538243131952775 0.4098540367859649" />
            </geometry>
            <material name="Green">
                <color rgba="0 1.0 0.0 1.0"/>
            </material>
        </visual>
        <collision>
            <origin xyz="0 0 0.6147810551789473" rpy="0 0 0"/>
            <geometry>
                <box size="0.7894706267661382 0.43538243131952775 0.4098540367859649" />
            </geometry>
        </collision>
    </link>
    <joint name="Torso_i0" type="revolute">
       <parent link="Torso"/>
       <child  link="i0"/>
       <origin rpy="0 1 0" xyz="0 0.21769121565976388 0.6147810551789473" />
     <axis xyz="1 0 0"/>
       <limit effort="0.0" lower="-3.14159" upper="3.14159" velocity="0.0"/>
    </joint>
    <link name="i0">
        <inertial>
            <origin xyz="0.3465779305980782 0.12831400033639664 0.3687702832719838" rpy="0 0 0"/>
            <mass value="1" />
            <inertia ixx="100" ixy="0" ixz="0" iyy="100" iyz="0" izz="100" />
        </inertial>
        <visual>
            <origin xyz="0.3465779305980782 0.12831400033639664 0.3687702832719838" rpy="0 0 0"/>
            <geometry>
                <box size="0.6931558611961564 0.2566280006727933 0.7375405665439676" />
            </geometry>
            <material name="Cyan">
                <color rgba="0 1.0 1.0 1.0"/>
            </material>
        </visual>
        <collision>
            <origin xyz="0.3465779305980782 0.12831400033639664 0.3687702832719838" rpy="0 0 0"/>
            <geometry>
                <box size="0.6931558611961564 0.2566280006727933 0.7375405665439676" />
            </geometry>
        </collision>
    </link>
</robot>