<robot name = "robot">
    <link name="Torso">
        <inertial>
            <origin xyz="0 0 1.4833681682372262" rpy="0 0 0"/>
            <mass value="1" />
            <inertia ixx="100" ixy="0" ixz="0" iyy="100" iyz="0" izz="100" />
        </inertial>
        <visual>
            <origin xyz="0 0 1.4833681682372262" rpy="0 0 0"/>
            <geometry>
                <box size="0.788306952859462 0.9711048967630712 0.9889121121581508" />
            </geometry>
            <material name="Green">
                <color rgba="0 1.0 0.0 1.0"/>
            </material>
        </visual>
        <collision>
            <origin xyz="0 0 1.4833681682372262" rpy="0 0 0"/>
            <geometry>
                <box size="0.788306952859462 0.9711048967630712 0.9889121121581508" />
            </geometry>
        </collision>
    </link>
    <joint name="Torso_i0" type="revolute">
       <parent link="Torso"/>
       <child  link="i0"/>
       <origin rpy="0 0 1" xyz="0 0.4855524483815356 1.4833681682372262" />
     <axis xyz="1 0 0"/>
       <limit effort="0.0" lower="-3.14159" upper="3.14159" velocity="0.0"/>
    </joint>
    <link name="i0">
        <inertial>
            <origin xyz="0.3277622571924733 0.2670055297547772 0.10053424344163063" rpy="0 0 0"/>
            <mass value="1" />
            <inertia ixx="100" ixy="0" ixz="0" iyy="100" iyz="0" izz="100" />
        </inertial>
        <visual>
            <origin xyz="0.3277622571924733 0.2670055297547772 0.10053424344163063" rpy="0 0 0"/>
            <geometry>
                <box size="0.6555245143849466 0.5340110595095544 0.20106848688326126" />
            </geometry>
            <material name="Green">
                <color rgba="0 1.0 0.0 1.0"/>
            </material>
        </visual>
        <collision>
            <origin xyz="0.3277622571924733 0.2670055297547772 0.10053424344163063" rpy="0 0 0"/>
            <geometry>
                <box size="0.6555245143849466 0.5340110595095544 0.20106848688326126" />
            </geometry>
        </collision>
    </link>
    <joint name="i0_i1" type="revolute">
       <parent link="i0"/>
       <child  link="i1"/>
       <origin rpy="1 0 0" xyz="0 0.5340110595095544 0" />
     <axis xyz="1 0 0"/>
       <limit effort="0.0" lower="-3.14159" upper="3.14159" velocity="0.0"/>
    </joint>
    <link name="i1">
        <inertial>
            <origin xyz="0.16646474268833428 0.26201022577881017 0.46790983821772636" rpy="0 0 0"/>
            <mass value="1" />
            <inertia ixx="100" ixy="0" ixz="0" iyy="100" iyz="0" izz="100" />
        </inertial>
        <visual>
            <origin xyz="0.16646474268833428 0.26201022577881017 0.46790983821772636" rpy="0 0 0"/>
            <geometry>
                <box size="0.33292948537666855 0.5240204515576203 0.9358196764354527" />
            </geometry>
            <material name="Cyan">
                <color rgba="0 1.0 1.0 1.0"/>
            </material>
        </visual>
        <collision>
            <origin xyz="0.16646474268833428 0.26201022577881017 0.46790983821772636" rpy="0 0 0"/>
            <geometry>
                <box size="0.33292948537666855 0.5240204515576203 0.9358196764354527" />
            </geometry>
        </collision>
    </link>
    <joint name="Torso_j0" type="revolute">
       <parent link="Torso"/>
       <child  link="j0"/>
       <origin rpy="0 0 1" xyz="0 -0.4855524483815356 1.4833681682372262" />
     <axis xyz="1 0 0"/>
       <limit effort="0.0" lower="-3.14159" upper="3.14159" velocity="0.0"/>
    </joint>
    <link name="j0">
        <inertial>
            <origin xyz="0.4135899595202345 -0.49890428366296435 0.2574207241918847" rpy="0 0 0"/>
            <mass value="1" />
            <inertia ixx="100" ixy="0" ixz="0" iyy="100" iyz="0" izz="100" />
        </inertial>
        <visual>
            <origin xyz="0.4135899595202345 -0.49890428366296435 0.2574207241918847" rpy="0 0 0"/>
            <geometry>
                <box size="0.827179919040469 0.9978085673259287 0.5148414483837694" />
            </geometry>
            <material name="Cyan">
                <color rgba="0 1.0 1.0 1.0"/>
            </material>
        </visual>
        <collision>
            <origin xyz="0.4135899595202345 -0.49890428366296435 0.2574207241918847" rpy="0 0 0"/>
            <geometry>
                <box size="0.827179919040469 0.9978085673259287 0.5148414483837694" />
            </geometry>
        </collision>
    </link>
    <joint name="Torso_k0" type="revolute">
       <parent link="Torso"/>
       <child  link="k0"/>
       <origin rpy="0 0 1" xyz="0 0 1.9778242243163016" />
     <axis xyz="1 0 0"/>
       <limit effort="0.0" lower="-3.14159" upper="3.14159" velocity="0.0"/>
    </joint>
    <link name="k0">
        <inertial>
            <origin xyz="0.3787344946024923 0.3580444179008567 0.31160571192759245" rpy="0 0 0"/>
            <mass value="1" />
            <inertia ixx="100" ixy="0" ixz="0" iyy="100" iyz="0" izz="100" />
        </inertial>
        <visual>
            <origin xyz="0.3787344946024923 0.3580444179008567 0.31160571192759245" rpy="0 0 0"/>
            <geometry>
                <box size="0.7574689892049846 0.7160888358017135 0.6232114238551849" />
            </geometry>
            <material name="Cyan">
                <color rgba="0 1.0 1.0 1.0"/>
            </material>
        </visual>
        <collision>
            <origin xyz="0.3787344946024923 0.3580444179008567 0.31160571192759245" rpy="0 0 0"/>
            <geometry>
                <box size="0.7574689892049846 0.7160888358017135 0.6232114238551849" />
            </geometry>
        </collision>
    </link>
</robot>