<robot name = "robot">
    <link name="Torso">
        <inertial>
            <origin xyz="0 0 1.728521399560242" rpy="0 0 0"/>
            <mass value="1" />
            <inertia ixx="100" ixy="0" ixz="0" iyy="100" iyz="0" izz="100" />
        </inertial>
        <visual>
            <origin xyz="0 0 1.728521399560242" rpy="0 0 0"/>
            <geometry>
                <box size="0.4270820660990066 1.0538899660439736 1.152347599706828" />
            </geometry>
            <material name="Green">
                <color rgba="0 1.0 0.0 1.0"/>
            </material>
        </visual>
        <collision>
            <origin xyz="0 0 1.728521399560242" rpy="0 0 0"/>
            <geometry>
                <box size="0.4270820660990066 1.0538899660439736 1.152347599706828" />
            </geometry>
        </collision>
    </link>
    <joint name="Torso_i0" type="revolute">
       <parent link="Torso"/>
       <child  link="i0"/>
       <origin rpy="1 0 0" xyz="0 0.5269449830219868 1.728521399560242" />
     <axis xyz="1 0 0"/>
       <limit effort="0.0" lower="-3.14159" upper="3.14159" velocity="0.0"/>
    </joint>
    <link name="i0">
        <inertial>
            <origin xyz="0.2331393474186383 0.10335041989360341 0.12034518582999586" rpy="0 0 0"/>
            <mass value="1" />
            <inertia ixx="100" ixy="0" ixz="0" iyy="100" iyz="0" izz="100" />
        </inertial>
        <visual>
            <origin xyz="0.2331393474186383 0.10335041989360341 0.12034518582999586" rpy="0 0 0"/>
            <geometry>
                <box size="0.4662786948372766 0.20670083978720682 0.24069037165999171" />
            </geometry>
            <material name="Green">
                <color rgba="0 1.0 0.0 1.0"/>
            </material>
        </visual>
        <collision>
            <origin xyz="0.2331393474186383 0.10335041989360341 0.12034518582999586" rpy="0 0 0"/>
            <geometry>
                <box size="0.4662786948372766 0.20670083978720682 0.24069037165999171" />
            </geometry>
        </collision>
    </link>
    <joint name="i0_i1" type="revolute">
       <parent link="i0"/>
       <child  link="i1"/>
       <origin rpy="1 0 0" xyz="0 0.20670083978720682 0" />
     <axis xyz="1 0 0"/>
       <limit effort="0.0" lower="-3.14159" upper="3.14159" velocity="0.0"/>
    </joint>
    <link name="i1">
        <inertial>
            <origin xyz="0.21356659181012783 0.47452757558273395 0.3075072389562804" rpy="0 0 0"/>
            <mass value="1" />
            <inertia ixx="100" ixy="0" ixz="0" iyy="100" iyz="0" izz="100" />
        </inertial>
        <visual>
            <origin xyz="0.21356659181012783 0.47452757558273395 0.3075072389562804" rpy="0 0 0"/>
            <geometry>
                <box size="0.42713318362025565 0.9490551511654679 0.6150144779125608" />
            </geometry>
            <material name="Green">
                <color rgba="0 1.0 0.0 1.0"/>
            </material>
        </visual>
        <collision>
            <origin xyz="0.21356659181012783 0.47452757558273395 0.3075072389562804" rpy="0 0 0"/>
            <geometry>
                <box size="0.42713318362025565 0.9490551511654679 0.6150144779125608" />
            </geometry>
        </collision>
    </link>
    <joint name="Torso_j0" type="revolute">
       <parent link="Torso"/>
       <child  link="j0"/>
       <origin rpy="0 0 1" xyz="0 -0.5269449830219868 1.728521399560242" />
     <axis xyz="1 0 0"/>
       <limit effort="0.0" lower="-3.14159" upper="3.14159" velocity="0.0"/>
    </joint>
    <link name="j0">
        <inertial>
            <origin xyz="0.17541746493652366 -0.11681215421376719 0.44671693257497946" rpy="0 0 0"/>
            <mass value="1" />
            <inertia ixx="100" ixy="0" ixz="0" iyy="100" iyz="0" izz="100" />
        </inertial>
        <visual>
            <origin xyz="0.17541746493652366 -0.11681215421376719 0.44671693257497946" rpy="0 0 0"/>
            <geometry>
                <box size="0.3508349298730473 0.23362430842753437 0.8934338651499589" />
            </geometry>
            <material name="Green">
                <color rgba="0 1.0 0.0 1.0"/>
            </material>
        </visual>
        <collision>
            <origin xyz="0.17541746493652366 -0.11681215421376719 0.44671693257497946" rpy="0 0 0"/>
            <geometry>
                <box size="0.3508349298730473 0.23362430842753437 0.8934338651499589" />
            </geometry>
        </collision>
    </link>
    <joint name="j0_j1" type="revolute">
       <parent link="j0"/>
       <child  link="j1"/>
       <origin rpy="1 0 0" xyz="0 -0.23362430842753437 0" />
     <axis xyz="1 0 0"/>
       <limit effort="0.0" lower="-3.14159" upper="3.14159" velocity="0.0"/>
    </joint>
    <link name="j1">
        <inertial>
            <origin xyz="0.4238893149165305 -0.3329803270050796 0.45832016586296176" rpy="0 0 0"/>
            <mass value="1" />
            <inertia ixx="100" ixy="0" ixz="0" iyy="100" iyz="0" izz="100" />
        </inertial>
        <visual>
            <origin xyz="0.4238893149165305 -0.3329803270050796 0.45832016586296176" rpy="0 0 0"/>
            <geometry>
                <box size="0.847778629833061 0.6659606540101592 0.9166403317259235" />
            </geometry>
            <material name="Green">
                <color rgba="0 1.0 0.0 1.0"/>
            </material>
        </visual>
        <collision>
            <origin xyz="0.4238893149165305 -0.3329803270050796 0.45832016586296176" rpy="0 0 0"/>
            <geometry>
                <box size="0.847778629833061 0.6659606540101592 0.9166403317259235" />
            </geometry>
        </collision>
    </link>
    <joint name="Torso_k0" type="revolute">
       <parent link="Torso"/>
       <child  link="k0"/>
       <origin rpy="0 0 1" xyz="0 0 2.304695199413656" />
     <axis xyz="1 0 0"/>
       <limit effort="0.0" lower="-3.14159" upper="3.14159" velocity="0.0"/>
    </joint>
    <link name="k0">
        <inertial>
            <origin xyz="0.3070460853579926 0.3079948682049812 0.4290740980391414" rpy="0 0 0"/>
            <mass value="1" />
            <inertia ixx="100" ixy="0" ixz="0" iyy="100" iyz="0" izz="100" />
        </inertial>
        <visual>
            <origin xyz="0.3070460853579926 0.3079948682049812 0.4290740980391414" rpy="0 0 0"/>
            <geometry>
                <box size="0.6140921707159852 0.6159897364099624 0.8581481960782829" />
            </geometry>
            <material name="Cyan">
                <color rgba="0 1.0 1.0 1.0"/>
            </material>
        </visual>
        <collision>
            <origin xyz="0.3070460853579926 0.3079948682049812 0.4290740980391414" rpy="0 0 0"/>
            <geometry>
                <box size="0.6140921707159852 0.6159897364099624 0.8581481960782829" />
            </geometry>
        </collision>
    </link>
    <joint name="k0_k1" type="revolute">
       <parent link="k0"/>
       <child  link="k1"/>
       <origin rpy="1 0 0" xyz="0 0 0.8581481960782829" />
     <axis xyz="1 0 0"/>
       <limit effort="0.0" lower="-3.14159" upper="3.14159" velocity="0.0"/>
    </joint>
    <link name="k1">
        <inertial>
            <origin xyz="0.4041922056883266 0.39826417730185104 0.4071770171496645" rpy="0 0 0"/>
            <mass value="1" />
            <inertia ixx="100" ixy="0" ixz="0" iyy="100" iyz="0" izz="100" />
        </inertial>
        <visual>
            <origin xyz="0.4041922056883266 0.39826417730185104 0.4071770171496645" rpy="0 0 0"/>
            <geometry>
                <box size="0.8083844113766532 0.7965283546037021 0.814354034299329" />
            </geometry>
            <material name="Cyan">
                <color rgba="0 1.0 1.0 1.0"/>
            </material>
        </visual>
        <collision>
            <origin xyz="0.4041922056883266 0.39826417730185104 0.4071770171496645" rpy="0 0 0"/>
            <geometry>
                <box size="0.8083844113766532 0.7965283546037021 0.814354034299329" />
            </geometry>
        </collision>
    </link>
</robot>