<robot name = "robot">
    <link name="Torso">
        <inertial>
            <origin xyz="0 0 1.1552316634068915" rpy="0 0 0"/>
            <mass value="1" />
            <inertia ixx="100" ixy="0" ixz="0" iyy="100" iyz="0" izz="100" />
        </inertial>
        <visual>
            <origin xyz="0 0 1.1552316634068915" rpy="0 0 0"/>
            <geometry>
                <box size="1.0472952589065423 0.5414331475600611 0.7701544422712611" />
            </geometry>
            <material name="Green">
                <color rgba="0 1.0 0.0 1.0"/>
            </material>
        </visual>
        <collision>
            <origin xyz="0 0 1.1552316634068915" rpy="0 0 0"/>
            <geometry>
                <box size="1.0472952589065423 0.5414331475600611 0.7701544422712611" />
            </geometry>
        </collision>
    </link>
    <joint name="Torso_i0" type="revolute">
       <parent link="Torso"/>
       <child  link="i0"/>
       <origin rpy="1 0 0" xyz="0 0.27071657378003056 1.1552316634068915" />
     <axis xyz="1 0 0"/>
       <limit effort="0.0" lower="-3.14159" upper="3.14159" velocity="0.0"/>
    </joint>
    <link name="i0">
        <inertial>
            <origin xyz="0.19696753037622813 0.4775303828735862 0.4481932438267452" rpy="0 0 0"/>
            <mass value="1" />
            <inertia ixx="100" ixy="0" ixz="0" iyy="100" iyz="0" izz="100" />
        </inertial>
        <visual>
            <origin xyz="0.19696753037622813 0.4775303828735862 0.4481932438267452" rpy="0 0 0"/>
            <geometry>
                <box size="0.39393506075245627 0.9550607657471724 0.8963864876534904" />
            </geometry>
            <material name="Green">
                <color rgba="0 1.0 0.0 1.0"/>
            </material>
        </visual>
        <collision>
            <origin xyz="0.19696753037622813 0.4775303828735862 0.4481932438267452" rpy="0 0 0"/>
            <geometry>
                <box size="0.39393506075245627 0.9550607657471724 0.8963864876534904" />
            </geometry>
        </collision>
    </link>
    <joint name="i0_i1" type="revolute">
       <parent link="i0"/>
       <child  link="i1"/>
       <origin rpy="1 0 0" xyz="0 0.9550607657471724 0" />
     <axis xyz="1 0 0"/>
       <limit effort="0.0" lower="-3.14159" upper="3.14159" velocity="0.0"/>
    </joint>
    <link name="i1">
        <inertial>
            <origin xyz="0.17522596362042583 0.16130434916038278 0.3981750656395012" rpy="0 0 0"/>
            <mass value="1" />
            <inertia ixx="100" ixy="0" ixz="0" iyy="100" iyz="0" izz="100" />
        </inertial>
        <visual>
            <origin xyz="0.17522596362042583 0.16130434916038278 0.3981750656395012" rpy="0 0 0"/>
            <geometry>
                <box size="0.35045192724085167 0.32260869832076555 0.7963501312790024" />
            </geometry>
            <material name="Green">
                <color rgba="0 1.0 0.0 1.0"/>
            </material>
        </visual>
        <collision>
            <origin xyz="0.17522596362042583 0.16130434916038278 0.3981750656395012" rpy="0 0 0"/>
            <geometry>
                <box size="0.35045192724085167 0.32260869832076555 0.7963501312790024" />
            </geometry>
        </collision>
    </link>
    <joint name="Torso_j0" type="revolute">
       <parent link="Torso"/>
       <child  link="j0"/>
       <origin rpy="0 0 1" xyz="0 -0.27071657378003056 1.1552316634068915" />
     <axis xyz="1 0 0"/>
       <limit effort="0.0" lower="-3.14159" upper="3.14159" velocity="0.0"/>
    </joint>
    <link name="j0">
        <inertial>
            <origin xyz="0.24048054019799442 -0.20099271625109885 0.18317767409652028" rpy="0 0 0"/>
            <mass value="1" />
            <inertia ixx="100" ixy="0" ixz="0" iyy="100" iyz="0" izz="100" />
        </inertial>
        <visual>
            <origin xyz="0.24048054019799442 -0.20099271625109885 0.18317767409652028" rpy="0 0 0"/>
            <geometry>
                <box size="0.48096108039598884 0.4019854325021977 0.36635534819304055" />
            </geometry>
            <material name="Green">
                <color rgba="0 1.0 0.0 1.0"/>
            </material>
        </visual>
        <collision>
            <origin xyz="0.24048054019799442 -0.20099271625109885 0.18317767409652028" rpy="0 0 0"/>
            <geometry>
                <box size="0.48096108039598884 0.4019854325021977 0.36635534819304055" />
            </geometry>
        </collision>
    </link>
    <joint name="Torso_k0" type="revolute">
       <parent link="Torso"/>
       <child  link="k0"/>
       <origin rpy="0 0 1" xyz="0 0 1.5403088845425221" />
     <axis xyz="1 0 0"/>
       <limit effort="0.0" lower="-3.14159" upper="3.14159" velocity="0.0"/>
    </joint>
    <link name="k0">
        <inertial>
            <origin xyz="0.23191164192948435 0.36112359013001305 0.27462220410366267" rpy="0 0 0"/>
            <mass value="1" />
            <inertia ixx="100" ixy="0" ixz="0" iyy="100" iyz="0" izz="100" />
        </inertial>
        <visual>
            <origin xyz="0.23191164192948435 0.36112359013001305 0.27462220410366267" rpy="0 0 0"/>
            <geometry>
                <box size="0.4638232838589687 0.7222471802600261 0.5492444082073253" />
            </geometry>
            <material name="Green">
                <color rgba="0 1.0 0.0 1.0"/>
            </material>
        </visual>
        <collision>
            <origin xyz="0.23191164192948435 0.36112359013001305 0.27462220410366267" rpy="0 0 0"/>
            <geometry>
                <box size="0.4638232838589687 0.7222471802600261 0.5492444082073253" />
            </geometry>
        </collision>
    </link>
</robot>