<robot name = "robot">
    <link name="Torso">
        <inertial>
            <origin xyz="0 0 1.6887325832692073" rpy="0 0 0"/>
            <mass value="1" />
            <inertia ixx="100" ixy="0" ixz="0" iyy="100" iyz="0" izz="100" />
        </inertial>
        <visual>
            <origin xyz="0 0 1.6887325832692073" rpy="0 0 0"/>
            <geometry>
                <box size="0.7270228655515488 0.7292258214042837 1.1258217221794715" />
            </geometry>
            <material name="Green">
                <color rgba="0 1.0 0.0 1.0"/>
            </material>
        </visual>
        <collision>
            <origin xyz="0 0 1.6887325832692073" rpy="0 0 0"/>
            <geometry>
                <box size="0.7270228655515488 0.7292258214042837 1.1258217221794715" />
            </geometry>
        </collision>
    </link>
    <joint name="Torso_i0" type="revolute">
       <parent link="Torso"/>
       <child  link="i0"/>
       <origin rpy="0 0 0" xyz="0 0.36461291070214186 1.6887325832692073" />
     <axis xyz="1 0 0"/>
       <limit effort="0.0" lower="-3.14159" upper="3.14159" velocity="0.0"/>
    </joint>
    <link name="i0">
        <inertial>
            <origin xyz="0.11224730973882174 0.4335990217150999 0.22449873514369667" rpy="0 0 0"/>
            <mass value="1" />
            <inertia ixx="100" ixy="0" ixz="0" iyy="100" iyz="0" izz="100" />
        </inertial>
        <visual>
            <origin xyz="0.11224730973882174 0.4335990217150999 0.22449873514369667" rpy="0 0 0"/>
            <geometry>
                <box size="0.2244946194776435 0.8671980434301998 0.44899747028739334" />
            </geometry>
            <material name="Red">
                <color rgba="1.0 0 0 1.0"/>
            </material>
        </visual>
        <collision>
            <origin xyz="0.11224730973882174 0.4335990217150999 0.22449873514369667" rpy="0 0 0"/>
            <geometry>
                <box size="0.2244946194776435 0.8671980434301998 0.44899747028739334" />
            </geometry>
        </collision>
    </link>
    <joint name="i0_i1" type="revolute">
       <parent link="i0"/>
       <child  link="i1"/>
       <origin rpy="1 0 0" xyz="0 0.8671980434301998 0" />
     <axis xyz="1 0 0"/>
       <limit effort="0.0" lower="-3.14159" upper="3.14159" velocity="0.0"/>
    </joint>
    <link name="i1">
        <inertial>
            <origin xyz="0.41554123044975566 0.12446875579189487 0.34344368693905936" rpy="0 0 0"/>
            <mass value="1" />
            <inertia ixx="100" ixy="0" ixz="0" iyy="100" iyz="0" izz="100" />
        </inertial>
        <visual>
            <origin xyz="0.41554123044975566 0.12446875579189487 0.34344368693905936" rpy="0 0 0"/>
            <geometry>
                <box size="0.8310824608995113 0.24893751158378974 0.6868873738781187" />
            </geometry>
            <material name="Red">
                <color rgba="1.0 0 0 1.0"/>
            </material>
        </visual>
        <collision>
            <origin xyz="0.41554123044975566 0.12446875579189487 0.34344368693905936" rpy="0 0 0"/>
            <geometry>
                <box size="0.8310824608995113 0.24893751158378974 0.6868873738781187" />
            </geometry>
        </collision>
    </link>
    <joint name="Torso_j0" type="revolute">
       <parent link="Torso"/>
       <child  link="j0"/>
       <origin rpy="0 0 1" xyz="0 -0.36461291070214186 1.6887325832692073" />
     <axis xyz="1 0 0"/>
       <limit effort="0.0" lower="-3.14159" upper="3.14159" velocity="0.0"/>
    </joint>
    <link name="j0">
        <inertial>
            <origin xyz="0.2878314333301114 -0.3696438328759396 0.15815804943866613" rpy="0 0 0"/>
            <mass value="1" />
            <inertia ixx="100" ixy="0" ixz="0" iyy="100" iyz="0" izz="100" />
        </inertial>
        <visual>
            <origin xyz="0.2878314333301114 -0.3696438328759396 0.15815804943866613" rpy="0 0 0"/>
            <geometry>
                <box size="0.5756628666602228 0.7392876657518792 0.31631609887733225" />
            </geometry>
            <material name="Cyan">
                <color rgba="0 1.0 1.0 1.0"/>
            </material>
        </visual>
        <collision>
            <origin xyz="0.2878314333301114 -0.3696438328759396 0.15815804943866613" rpy="0 0 0"/>
            <geometry>
                <box size="0.5756628666602228 0.7392876657518792 0.31631609887733225" />
            </geometry>
        </collision>
    </link>
    <joint name="j0_j1" type="revolute">
       <parent link="j0"/>
       <child  link="j1"/>
       <origin rpy="1 0 0" xyz="0 -0.7392876657518792 0" />
     <axis xyz="1 0 0"/>
       <limit effort="0.0" lower="-3.14159" upper="3.14159" velocity="0.0"/>
    </joint>
    <link name="j1">
        <inertial>
            <origin xyz="0.4975799970629985 -0.31379290089708706 0.3030036082129288" rpy="0 0 0"/>
            <mass value="1" />
            <inertia ixx="100" ixy="0" ixz="0" iyy="100" iyz="0" izz="100" />
        </inertial>
        <visual>
            <origin xyz="0.4975799970629985 -0.31379290089708706 0.3030036082129288" rpy="0 0 0"/>
            <geometry>
                <box size="0.995159994125997 0.6275858017941741 0.6060072164258576" />
            </geometry>
            <material name="Green">
                <color rgba="0 1.0 0.0 1.0"/>
            </material>
        </visual>
        <collision>
            <origin xyz="0.4975799970629985 -0.31379290089708706 0.3030036082129288" rpy="0 0 0"/>
            <geometry>
                <box size="0.995159994125997 0.6275858017941741 0.6060072164258576" />
            </geometry>
        </collision>
    </link>
    <joint name="Torso_k0" type="revolute">
       <parent link="Torso"/>
       <child  link="k0"/>
       <origin rpy="0 0 1" xyz="0 0 2.251643444358943" />
     <axis xyz="1 0 0"/>
       <limit effort="0.0" lower="-3.14159" upper="3.14159" velocity="0.0"/>
    </joint>
    <link name="k0">
        <inertial>
            <origin xyz="0.18015964041625204 0.44405561111119507 0.2376241678432224" rpy="0 0 0"/>
            <mass value="1" />
            <inertia ixx="100" ixy="0" ixz="0" iyy="100" iyz="0" izz="100" />
        </inertial>
        <visual>
            <origin xyz="0.18015964041625204 0.44405561111119507 0.2376241678432224" rpy="0 0 0"/>
            <geometry>
                <box size="0.3603192808325041 0.8881112222223901 0.4752483356864448" />
            </geometry>
            <material name="Green">
                <color rgba="0 1.0 0.0 1.0"/>
            </material>
        </visual>
        <collision>
            <origin xyz="0.18015964041625204 0.44405561111119507 0.2376241678432224" rpy="0 0 0"/>
            <geometry>
                <box size="0.3603192808325041 0.8881112222223901 0.4752483356864448" />
            </geometry>
        </collision>
    </link>
    <joint name="k0_k1" type="revolute">
       <parent link="k0"/>
       <child  link="k1"/>
       <origin rpy="1 0 0" xyz="0 0 0.4752483356864448" />
     <axis xyz="1 0 0"/>
       <limit effort="0.0" lower="-3.14159" upper="3.14159" velocity="0.0"/>
    </joint>
    <link name="k1">
        <inertial>
            <origin xyz="0.4101973910061324 0.21353497600103416 0.1607616564814296" rpy="0 0 0"/>
            <mass value="1" />
            <inertia ixx="100" ixy="0" ixz="0" iyy="100" iyz="0" izz="100" />
        </inertial>
        <visual>
            <origin xyz="0.4101973910061324 0.21353497600103416 0.1607616564814296" rpy="0 0 0"/>
            <geometry>
                <box size="0.8203947820122648 0.4270699520020683 0.3215233129628592" />
            </geometry>
            <material name="Cyan">
                <color rgba="0 1.0 1.0 1.0"/>
            </material>
        </visual>
        <collision>
            <origin xyz="0.4101973910061324 0.21353497600103416 0.1607616564814296" rpy="0 0 0"/>
            <geometry>
                <box size="0.8203947820122648 0.4270699520020683 0.3215233129628592" />
            </geometry>
        </collision>
    </link>
</robot>