<robot name = "robot">
    <link name="Torso">
        <inertial>
            <origin xyz="0 0 0.6968726327450769" rpy="0 0 0"/>
            <mass value="1" />
            <inertia ixx="100" ixy="0" ixz="0" iyy="100" iyz="0" izz="100" />
        </inertial>
        <visual>
            <origin xyz="0 0 0.6968726327450769" rpy="0 0 0"/>
            <geometry>
                <box size="0.46167313819334416 0.7502481053079376 0.4645817551633846" />
            </geometry>
            <material name="Green">
                <color rgba="0 1.0 0.0 1.0"/>
            </material>
        </visual>
        <collision>
            <origin xyz="0 0 0.6968726327450769" rpy="0 0 0"/>
            <geometry>
                <box size="0.46167313819334416 0.7502481053079376 0.4645817551633846" />
            </geometry>
        </collision>
    </link>
    <joint name="Torso_i0" type="revolute">
       <parent link="Torso"/>
       <child  link="i0"/>
       <origin rpy="1 0 0" xyz="0 0.3751240526539688 0.6968726327450769" />
     <axis xyz="1 0 0"/>
       <limit effort="0.0" lower="-3.14159" upper="3.14159" velocity="0.0"/>
    </joint>
    <link name="i0">
        <inertial>
            <origin xyz="0.39805731476272543 0.31812732643170316 0.15096879712564149" rpy="0 0 0"/>
            <mass value="1" />
            <inertia ixx="100" ixy="0" ixz="0" iyy="100" iyz="0" izz="100" />
        </inertial>
        <visual>
            <origin xyz="0.39805731476272543 0.31812732643170316 0.15096879712564149" rpy="0 0 0"/>
            <geometry>
                <box size="0.7961146295254509 0.6362546528634063 0.30193759425128297" />
            </geometry>
            <material name="Green">
                <color rgba="0 1.0 0.0 1.0"/>
            </material>
        </visual>
        <collision>
            <origin xyz="0.39805731476272543 0.31812732643170316 0.15096879712564149" rpy="0 0 0"/>
            <geometry>
                <box size="0.7961146295254509 0.6362546528634063 0.30193759425128297" />
            </geometry>
        </collision>
    </link>
    <joint name="i0_i1" type="revolute">
       <parent link="i0"/>
       <child  link="i1"/>
       <origin rpy="1 0 0" xyz="0 0.6362546528634063 0" />
     <axis xyz="1 0 0"/>
       <limit effort="0.0" lower="-3.14159" upper="3.14159" velocity="0.0"/>
    </joint>
    <link name="i1">
        <inertial>
            <origin xyz="0.1327407469654389 0.17543814496821175 0.16866666436612268" rpy="0 0 0"/>
            <mass value="1" />
            <inertia ixx="100" ixy="0" ixz="0" iyy="100" iyz="0" izz="100" />
        </inertial>
        <visual>
            <origin xyz="0.1327407469654389 0.17543814496821175 0.16866666436612268" rpy="0 0 0"/>
            <geometry>
                <box size="0.2654814939308778 0.3508762899364235 0.33733332873224536" />
            </geometry>
            <material name="Cyan">
                <color rgba="0 1.0 1.0 1.0"/>
            </material>
        </visual>
        <collision>
            <origin xyz="0.1327407469654389 0.17543814496821175 0.16866666436612268" rpy="0 0 0"/>
            <geometry>
                <box size="0.2654814939308778 0.3508762899364235 0.33733332873224536" />
            </geometry>
        </collision>
    </link>
    <joint name="i1_i2" type="revolute">
       <parent link="i1"/>
       <child  link="i2"/>
       <origin rpy="1 0 0" xyz="0 0.3508762899364235 0" />
     <axis xyz="1 0 0"/>
       <limit effort="0.0" lower="-3.14159" upper="3.14159" velocity="0.0"/>
    </joint>
    <link name="i2">
        <inertial>
            <origin xyz="0.3725820597421996 0.49285099234525886 0.46905379549026605" rpy="0 0 0"/>
            <mass value="1" />
            <inertia ixx="100" ixy="0" ixz="0" iyy="100" iyz="0" izz="100" />
        </inertial>
        <visual>
            <origin xyz="0.3725820597421996 0.49285099234525886 0.46905379549026605" rpy="0 0 0"/>
            <geometry>
                <box size="0.7451641194843992 0.9857019846905177 0.9381075909805321" />
            </geometry>
            <material name="Green">
                <color rgba="0 1.0 0.0 1.0"/>
            </material>
        </visual>
        <collision>
            <origin xyz="0.3725820597421996 0.49285099234525886 0.46905379549026605" rpy="0 0 0"/>
            <geometry>
                <box size="0.7451641194843992 0.9857019846905177 0.9381075909805321" />
            </geometry>
        </collision>
    </link>
    <joint name="Torso_j0" type="revolute">
       <parent link="Torso"/>
       <child  link="j0"/>
       <origin rpy="0 0 1" xyz="0 -0.3751240526539688 0.6968726327450769" />
     <axis xyz="1 0 0"/>
       <limit effort="0.0" lower="-3.14159" upper="3.14159" velocity="0.0"/>
    </joint>
    <link name="j0">
        <inertial>
            <origin xyz="0.18141038496488224 -0.2597708020101517 0.15499878690738966" rpy="0 0 0"/>
            <mass value="1" />
            <inertia ixx="100" ixy="0" ixz="0" iyy="100" iyz="0" izz="100" />
        </inertial>
        <visual>
            <origin xyz="0.18141038496488224 -0.2597708020101517 0.15499878690738966" rpy="0 0 0"/>
            <geometry>
                <box size="0.3628207699297645 0.5195416040203034 0.3099975738147793" />
            </geometry>
            <material name="Cyan">
                <color rgba="0 1.0 1.0 1.0"/>
            </material>
        </visual>
        <collision>
            <origin xyz="0.18141038496488224 -0.2597708020101517 0.15499878690738966" rpy="0 0 0"/>
            <geometry>
                <box size="0.3628207699297645 0.5195416040203034 0.3099975738147793" />
            </geometry>
        </collision>
    </link>
    <joint name="j0_j1" type="revolute">
       <parent link="j0"/>
       <child  link="j1"/>
       <origin rpy="1 0 0" xyz="0 -0.5195416040203034 0" />
     <axis xyz="1 0 0"/>
       <limit effort="0.0" lower="-3.14159" upper="3.14159" velocity="0.0"/>
    </joint>
    <link name="j1">
        <inertial>
            <origin xyz="0.11889600728547603 -0.10298610144472581 0.2208170483784131" rpy="0 0 0"/>
            <mass value="1" />
            <inertia ixx="100" ixy="0" ixz="0" iyy="100" iyz="0" izz="100" />
        </inertial>
        <visual>
            <origin xyz="0.11889600728547603 -0.10298610144472581 0.2208170483784131" rpy="0 0 0"/>
            <geometry>
                <box size="0.23779201457095206 0.20597220288945162 0.4416340967568262" />
            </geometry>
            <material name="Cyan">
                <color rgba="0 1.0 1.0 1.0"/>
            </material>
        </visual>
        <collision>
            <origin xyz="0.11889600728547603 -0.10298610144472581 0.2208170483784131" rpy="0 0 0"/>
            <geometry>
                <box size="0.23779201457095206 0.20597220288945162 0.4416340967568262" />
            </geometry>
        </collision>
    </link>
    <joint name="j1_j2" type="revolute">
       <parent link="j1"/>
       <child  link="j2"/>
       <origin rpy="1 0 0" xyz="0 -0.20597220288945162 0" />
     <axis xyz="1 0 0"/>
       <limit effort="0.0" lower="-3.14159" upper="3.14159" velocity="0.0"/>
    </joint>
    <link name="j2">
        <inertial>
            <origin xyz="0.1609558504030679 -0.2602335993122922 0.3764124617178569" rpy="0 0 0"/>
            <mass value="1" />
            <inertia ixx="100" ixy="0" ixz="0" iyy="100" iyz="0" izz="100" />
        </inertial>
        <visual>
            <origin xyz="0.1609558504030679 -0.2602335993122922 0.3764124617178569" rpy="0 0 0"/>
            <geometry>
                <box size="0.3219117008061358 0.5204671986245843 0.7528249234357138" />
            </geometry>
            <material name="Cyan">
                <color rgba="0 1.0 1.0 1.0"/>
            </material>
        </visual>
        <collision>
            <origin xyz="0.1609558504030679 -0.2602335993122922 0.3764124617178569" rpy="0 0 0"/>
            <geometry>
                <box size="0.3219117008061358 0.5204671986245843 0.7528249234357138" />
            </geometry>
        </collision>
    </link>
    <joint name="Torso_k0" type="revolute">
       <parent link="Torso"/>
       <child  link="k0"/>
       <origin rpy="0 0 1" xyz="0 0 0.9291635103267692" />
     <axis xyz="1 0 0"/>
       <limit effort="0.0" lower="-3.14159" upper="3.14159" velocity="0.0"/>
    </joint>
    <link name="k0">
        <inertial>
            <origin xyz="0.3002884298491172 0.2822569213098922 0.4127158531532785" rpy="0 0 0"/>
            <mass value="1" />
            <inertia ixx="100" ixy="0" ixz="0" iyy="100" iyz="0" izz="100" />
        </inertial>
        <visual>
            <origin xyz="0.3002884298491172 0.2822569213098922 0.4127158531532785" rpy="0 0 0"/>
            <geometry>
                <box size="0.6005768596982344 0.5645138426197844 0.825431706306557" />
            </geometry>
            <material name="Cyan">
                <color rgba="0 1.0 1.0 1.0"/>
            </material>
        </visual>
        <collision>
            <origin xyz="0.3002884298491172 0.2822569213098922 0.4127158531532785" rpy="0 0 0"/>
            <geometry>
                <box size="0.6005768596982344 0.5645138426197844 0.825431706306557" />
            </geometry>
        </collision>
    </link>
</robot>