<robot name = "robot">
    <link name="Torso">
        <inertial>
            <origin xyz="0 0 0.948732846368582" rpy="0 0 0"/>
            <mass value="1" />
            <inertia ixx="100" ixy="0" ixz="0" iyy="100" iyz="0" izz="100" />
        </inertial>
        <visual>
            <origin xyz="0 0 0.948732846368582" rpy="0 0 0"/>
            <geometry>
                <box size="0.7890828592531253 0.8464220222632227 0.6324885642457213" />
            </geometry>
            <material name="Green">
                <color rgba="0 1.0 0.0 1.0"/>
            </material>
        </visual>
        <collision>
            <origin xyz="0 0 0.948732846368582" rpy="0 0 0"/>
            <geometry>
                <box size="0.7890828592531253 0.8464220222632227 0.6324885642457213" />
            </geometry>
        </collision>
    </link>
    <joint name="Torso_i0" type="revolute">
       <parent link="Torso"/>
       <child  link="i0"/>
       <origin rpy="0 0 1" xyz="0 0.42321101113161136 0.948732846368582" />
     <axis xyz="1 0 0"/>
       <limit effort="0.0" lower="-3.14159" upper="3.14159" velocity="0.0"/>
    </joint>
    <link name="i0">
        <inertial>
            <origin xyz="0.20151852455062502 0.3552478799278238 0.13302664961710514" rpy="0 0 0"/>
            <mass value="1" />
            <inertia ixx="100" ixy="0" ixz="0" iyy="100" iyz="0" izz="100" />
        </inertial>
        <visual>
            <origin xyz="0.20151852455062502 0.3552478799278238 0.13302664961710514" rpy="0 0 0"/>
            <geometry>
                <box size="0.40303704910125004 0.7104957598556476 0.2660532992342103" />
            </geometry>
            <material name="Green">
                <color rgba="0 1.0 0.0 1.0"/>
            </material>
        </visual>
        <collision>
            <origin xyz="0.20151852455062502 0.3552478799278238 0.13302664961710514" rpy="0 0 0"/>
            <geometry>
                <box size="0.40303704910125004 0.7104957598556476 0.2660532992342103" />
            </geometry>
        </collision>
    </link>
    <joint name="i0_i1" type="revolute">
       <parent link="i0"/>
       <child  link="i1"/>
       <origin rpy="1 0 0" xyz="0 0.7104957598556476 0" />
     <axis xyz="1 0 0"/>
       <limit effort="0.0" lower="-3.14159" upper="3.14159" velocity="0.0"/>
    </joint>
    <link name="i1">
        <inertial>
            <origin xyz="0.12269136409859974 0.23915284113659818 0.17910708014901086" rpy="0 0 0"/>
            <mass value="1" />
            <inertia ixx="100" ixy="0" ixz="0" iyy="100" iyz="0" izz="100" />
        </inertial>
        <visual>
            <origin xyz="0.12269136409859974 0.23915284113659818 0.17910708014901086" rpy="0 0 0"/>
            <geometry>
                <box size="0.24538272819719947 0.47830568227319636 0.3582141602980217" />
            </geometry>
            <material name="Cyan">
                <color rgba="0 1.0 1.0 1.0"/>
            </material>
        </visual>
        <collision>
            <origin xyz="0.12269136409859974 0.23915284113659818 0.17910708014901086" rpy="0 0 0"/>
            <geometry>
                <box size="0.24538272819719947 0.47830568227319636 0.3582141602980217" />
            </geometry>
        </collision>
    </link>
    <joint name="Torso_j0" type="revolute">
       <parent link="Torso"/>
       <child  link="j0"/>
       <origin rpy="0 0 1" xyz="0 -0.42321101113161136 0.948732846368582" />
     <axis xyz="1 0 0"/>
       <limit effort="0.0" lower="-3.14159" upper="3.14159" velocity="0.0"/>
    </joint>
    <link name="j0">
        <inertial>
            <origin xyz="0.4567678016616479 -0.21710551524839833 0.2655216648806037" rpy="0 0 0"/>
            <mass value="1" />
            <inertia ixx="100" ixy="0" ixz="0" iyy="100" iyz="0" izz="100" />
        </inertial>
        <visual>
            <origin xyz="0.4567678016616479 -0.21710551524839833 0.2655216648806037" rpy="0 0 0"/>
            <geometry>
                <box size="0.9135356033232958 0.43421103049679666 0.5310433297612074" />
            </geometry>
            <material name="Green">
                <color rgba="0 1.0 0.0 1.0"/>
            </material>
        </visual>
        <collision>
            <origin xyz="0.4567678016616479 -0.21710551524839833 0.2655216648806037" rpy="0 0 0"/>
            <geometry>
                <box size="0.9135356033232958 0.43421103049679666 0.5310433297612074" />
            </geometry>
        </collision>
    </link>
    <joint name="Torso_k0" type="revolute">
       <parent link="Torso"/>
       <child  link="k0"/>
       <origin rpy="0 0 1" xyz="0 0 1.2649771284914426" />
     <axis xyz="1 0 0"/>
       <limit effort="0.0" lower="-3.14159" upper="3.14159" velocity="0.0"/>
    </joint>
    <link name="k0">
        <inertial>
            <origin xyz="0.40111526609070103 0.20670896477427636 0.22251585098893628" rpy="0 0 0"/>
            <mass value="1" />
            <inertia ixx="100" ixy="0" ixz="0" iyy="100" iyz="0" izz="100" />
        </inertial>
        <visual>
            <origin xyz="0.40111526609070103 0.20670896477427636 0.22251585098893628" rpy="0 0 0"/>
            <geometry>
                <box size="0.8022305321814021 0.4134179295485527 0.44503170197787256" />
            </geometry>
            <material name="Cyan">
                <color rgba="0 1.0 1.0 1.0"/>
            </material>
        </visual>
        <collision>
            <origin xyz="0.40111526609070103 0.20670896477427636 0.22251585098893628" rpy="0 0 0"/>
            <geometry>
                <box size="0.8022305321814021 0.4134179295485527 0.44503170197787256" />
            </geometry>
        </collision>
    </link>
</robot>