<robot name = "robot">
    <link name="Torso">
        <inertial>
            <origin xyz="0 0 1.330132658217762" rpy="0 0 0"/>
            <mass value="1" />
            <inertia ixx="100" ixy="0" ixz="0" iyy="100" iyz="0" izz="100" />
        </inertial>
        <visual>
            <origin xyz="0 0 1.330132658217762" rpy="0 0 0"/>
            <geometry>
                <box size="0.621641728329736 0.6407264316567994 0.8867551054785079" />
            </geometry>
            <material name="Green">
                <color rgba="0 1.0 0.0 1.0"/>
            </material>
        </visual>
        <collision>
            <origin xyz="0 0 1.330132658217762" rpy="0 0 0"/>
            <geometry>
                <box size="0.621641728329736 0.6407264316567994 0.8867551054785079" />
            </geometry>
        </collision>
    </link>
    <joint name="Torso_i0" type="revolute">
       <parent link="Torso"/>
       <child  link="i0"/>
       <origin rpy="0 1 0" xyz="0 0.3203632158283997 1.330132658217762" />
     <axis xyz="1 0 0"/>
       <limit effort="0.0" lower="-3.14159" upper="3.14159" velocity="0.0"/>
    </joint>
    <link name="i0">
        <inertial>
            <origin xyz="0.13426080048116693 0.4928471665498909 0.28993991296396626" rpy="0 0 0"/>
            <mass value="1" />
            <inertia ixx="100" ixy="0" ixz="0" iyy="100" iyz="0" izz="100" />
        </inertial>
        <visual>
            <origin xyz="0.13426080048116693 0.4928471665498909 0.28993991296396626" rpy="0 0 0"/>
            <geometry>
                <box size="0.26852160096233385 0.9856943330997818 0.5798798259279325" />
            </geometry>
            <material name="Green">
                <color rgba="0 1.0 0.0 1.0"/>
            </material>
        </visual>
        <collision>
            <origin xyz="0.13426080048116693 0.4928471665498909 0.28993991296396626" rpy="0 0 0"/>
            <geometry>
                <box size="0.26852160096233385 0.9856943330997818 0.5798798259279325" />
            </geometry>
        </collision>
    </link>
    <joint name="Torso_j0" type="revolute">
       <parent link="Torso"/>
       <child  link="j0"/>
       <origin rpy="0 0 1" xyz="0 -0.3203632158283997 1.330132658217762" />
     <axis xyz="1 0 0"/>
       <limit effort="0.0" lower="-3.14159" upper="3.14159" velocity="0.0"/>
    </joint>
    <link name="j0">
        <inertial>
            <origin xyz="0.3916399238977063 -0.41008823504625225 0.26306705179579026" rpy="0 0 0"/>
            <mass value="1" />
            <inertia ixx="100" ixy="0" ixz="0" iyy="100" iyz="0" izz="100" />
        </inertial>
        <visual>
            <origin xyz="0.3916399238977063 -0.41008823504625225 0.26306705179579026" rpy="0 0 0"/>
            <geometry>
                <box size="0.7832798477954126 0.8201764700925045 0.5261341035915805" />
            </geometry>
            <material name="Green">
                <color rgba="0 1.0 0.0 1.0"/>
            </material>
        </visual>
        <collision>
            <origin xyz="0.3916399238977063 -0.41008823504625225 0.26306705179579026" rpy="0 0 0"/>
            <geometry>
                <box size="0.7832798477954126 0.8201764700925045 0.5261341035915805" />
            </geometry>
        </collision>
    </link>
    <joint name="j0_j1" type="revolute">
       <parent link="j0"/>
       <child  link="j1"/>
       <origin rpy="1 0 0" xyz="0 -0.8201764700925045 0" />
     <axis xyz="1 0 0"/>
       <limit effort="0.0" lower="-3.14159" upper="3.14159" velocity="0.0"/>
    </joint>
    <link name="j1">
        <inertial>
            <origin xyz="0.21102627362394563 -0.27924126124442816 0.1978828047634852" rpy="0 0 0"/>
            <mass value="1" />
            <inertia ixx="100" ixy="0" ixz="0" iyy="100" iyz="0" izz="100" />
        </inertial>
        <visual>
            <origin xyz="0.21102627362394563 -0.27924126124442816 0.1978828047634852" rpy="0 0 0"/>
            <geometry>
                <box size="0.42205254724789126 0.5584825224888563 0.3957656095269704" />
            </geometry>
            <material name="Green">
                <color rgba="0 1.0 0.0 1.0"/>
            </material>
        </visual>
        <collision>
            <origin xyz="0.21102627362394563 -0.27924126124442816 0.1978828047634852" rpy="0 0 0"/>
            <geometry>
                <box size="0.42205254724789126 0.5584825224888563 0.3957656095269704" />
            </geometry>
        </collision>
    </link>
    <joint name="Torso_k0" type="revolute">
       <parent link="Torso"/>
       <child  link="k0"/>
       <origin rpy="0 0 1" xyz="0 0 1.7735102109570158" />
     <axis xyz="1 0 0"/>
       <limit effort="0.0" lower="-3.14159" upper="3.14159" velocity="0.0"/>
    </joint>
    <link name="k0">
        <inertial>
            <origin xyz="0.4278597202536807 0.3458874944469703 0.2282484944170034" rpy="0 0 0"/>
            <mass value="1" />
            <inertia ixx="100" ixy="0" ixz="0" iyy="100" iyz="0" izz="100" />
        </inertial>
        <visual>
            <origin xyz="0.4278597202536807 0.3458874944469703 0.2282484944170034" rpy="0 0 0"/>
            <geometry>
                <box size="0.8557194405073614 0.6917749888939406 0.4564969888340068" />
            </geometry>
            <material name="Cyan">
                <color rgba="0 1.0 1.0 1.0"/>
            </material>
        </visual>
        <collision>
            <origin xyz="0.4278597202536807 0.3458874944469703 0.2282484944170034" rpy="0 0 0"/>
            <geometry>
                <box size="0.8557194405073614 0.6917749888939406 0.4564969888340068" />
            </geometry>
        </collision>
    </link>
    <joint name="k0_k1" type="revolute">
       <parent link="k0"/>
       <child  link="k1"/>
       <origin rpy="1 0 0" xyz="0 0 0.4564969888340068" />
     <axis xyz="1 0 0"/>
       <limit effort="0.0" lower="-3.14159" upper="3.14159" velocity="0.0"/>
    </joint>
    <link name="k1">
        <inertial>
            <origin xyz="0.2498917551337356 0.18425648108150933 0.3065824189773876" rpy="0 0 0"/>
            <mass value="1" />
            <inertia ixx="100" ixy="0" ixz="0" iyy="100" iyz="0" izz="100" />
        </inertial>
        <visual>
            <origin xyz="0.2498917551337356 0.18425648108150933 0.3065824189773876" rpy="0 0 0"/>
            <geometry>
                <box size="0.4997835102674712 0.36851296216301865 0.6131648379547752" />
            </geometry>
            <material name="Cyan">
                <color rgba="0 1.0 1.0 1.0"/>
            </material>
        </visual>
        <collision>
            <origin xyz="0.2498917551337356 0.18425648108150933 0.3065824189773876" rpy="0 0 0"/>
            <geometry>
                <box size="0.4997835102674712 0.36851296216301865 0.6131648379547752" />
            </geometry>
        </collision>
    </link>
</robot>