<robot name = "robot">
    <link name="Torso">
        <inertial>
            <origin xyz="0 0 1.2359697168014252" rpy="0 0 0"/>
            <mass value="1" />
            <inertia ixx="100" ixy="0" ixz="0" iyy="100" iyz="0" izz="100" />
        </inertial>
        <visual>
            <origin xyz="0 0 1.2359697168014252" rpy="0 0 0"/>
            <geometry>
                <box size="0.7529571588559673 0.8072298207370892 0.8239798112009502" />
            </geometry>
            <material name="Green">
                <color rgba="0 1.0 0.0 1.0"/>
            </material>
        </visual>
        <collision>
            <origin xyz="0 0 1.2359697168014252" rpy="0 0 0"/>
            <geometry>
                <box size="0.7529571588559673 0.8072298207370892 0.8239798112009502" />
            </geometry>
        </collision>
    </link>
    <joint name="Torso_i0" type="revolute">
       <parent link="Torso"/>
       <child  link="i0"/>
       <origin rpy="0 0 0" xyz="0 0.4036149103685446 1.2359697168014252" />
     <axis xyz="1 0 0"/>
       <limit effort="0.0" lower="-3.14159" upper="3.14159" velocity="0.0"/>
    </joint>
    <link name="i0">
        <inertial>
            <origin xyz="0.2227501026809319 0.4804558294601813 0.3869893671358047" rpy="0 0 0"/>
            <mass value="1" />
            <inertia ixx="100" ixy="0" ixz="0" iyy="100" iyz="0" izz="100" />
        </inertial>
        <visual>
            <origin xyz="0.2227501026809319 0.4804558294601813 0.3869893671358047" rpy="0 0 0"/>
            <geometry>
                <box size="0.4455002053618638 0.9609116589203626 0.7739787342716093" />
            </geometry>
            <material name="Green">
                <color rgba="0 1.0 0.0 1.0"/>
            </material>
        </visual>
        <collision>
            <origin xyz="0.2227501026809319 0.4804558294601813 0.3869893671358047" rpy="0 0 0"/>
            <geometry>
                <box size="0.4455002053618638 0.9609116589203626 0.7739787342716093" />
            </geometry>
        </collision>
    </link>
    <joint name="i0_i1" type="revolute">
       <parent link="i0"/>
       <child  link="i1"/>
       <origin rpy="1 0 0" xyz="0 0.9609116589203626 0" />
     <axis xyz="1 0 0"/>
       <limit effort="0.0" lower="-3.14159" upper="3.14159" velocity="0.0"/>
    </joint>
    <link name="i1">
        <inertial>
            <origin xyz="0.2836506680758393 0.2748376385519584 0.2081936135879154" rpy="0 0 0"/>
            <mass value="1" />
            <inertia ixx="100" ixy="0" ixz="0" iyy="100" iyz="0" izz="100" />
        </inertial>
        <visual>
            <origin xyz="0.2836506680758393 0.2748376385519584 0.2081936135879154" rpy="0 0 0"/>
            <geometry>
                <box size="0.5673013361516785 0.5496752771039168 0.4163872271758308" />
            </geometry>
            <material name="Green">
                <color rgba="0 1.0 0.0 1.0"/>
            </material>
        </visual>
        <collision>
            <origin xyz="0.2836506680758393 0.2748376385519584 0.2081936135879154" rpy="0 0 0"/>
            <geometry>
                <box size="0.5673013361516785 0.5496752771039168 0.4163872271758308" />
            </geometry>
        </collision>
    </link>
    <joint name="Torso_j0" type="revolute">
       <parent link="Torso"/>
       <child  link="j0"/>
       <origin rpy="0 0 1" xyz="0 -0.4036149103685446 1.2359697168014252" />
     <axis xyz="1 0 0"/>
       <limit effort="0.0" lower="-3.14159" upper="3.14159" velocity="0.0"/>
    </joint>
    <link name="j0">
        <inertial>
            <origin xyz="0.4335255546171918 -0.1233992657087764 0.18771475730511225" rpy="0 0 0"/>
            <mass value="1" />
            <inertia ixx="100" ixy="0" ixz="0" iyy="100" iyz="0" izz="100" />
        </inertial>
        <visual>
            <origin xyz="0.4335255546171918 -0.1233992657087764 0.18771475730511225" rpy="0 0 0"/>
            <geometry>
                <box size="0.8670511092343836 0.2467985314175528 0.3754295146102245" />
            </geometry>
            <material name="Green">
                <color rgba="0 1.0 0.0 1.0"/>
            </material>
        </visual>
        <collision>
            <origin xyz="0.4335255546171918 -0.1233992657087764 0.18771475730511225" rpy="0 0 0"/>
            <geometry>
                <box size="0.8670511092343836 0.2467985314175528 0.3754295146102245" />
            </geometry>
        </collision>
    </link>
    <joint name="j0_j1" type="revolute">
       <parent link="j0"/>
       <child  link="j1"/>
       <origin rpy="1 0 0" xyz="0 -0.2467985314175528 0" />
     <axis xyz="1 0 0"/>
       <limit effort="0.0" lower="-3.14159" upper="3.14159" velocity="0.0"/>
    </joint>
    <link name="j1">
        <inertial>
            <origin xyz="0.4899137426095215 -0.2362587464674078 0.10948557477276398" rpy="0 0 0"/>
            <mass value="1" />
            <inertia ixx="100" ixy="0" ixz="0" iyy="100" iyz="0" izz="100" />
        </inertial>
        <visual>
            <origin xyz="0.4899137426095215 -0.2362587464674078 0.10948557477276398" rpy="0 0 0"/>
            <geometry>
                <box size="0.979827485219043 0.4725174929348156 0.21897114954552796" />
            </geometry>
            <material name="Cyan">
                <color rgba="0 1.0 1.0 1.0"/>
            </material>
        </visual>
        <collision>
            <origin xyz="0.4899137426095215 -0.2362587464674078 0.10948557477276398" rpy="0 0 0"/>
            <geometry>
                <box size="0.979827485219043 0.4725174929348156 0.21897114954552796" />
            </geometry>
        </collision>
    </link>
    <joint name="Torso_k0" type="revolute">
       <parent link="Torso"/>
       <child  link="k0"/>
       <origin rpy="0 0 1" xyz="0 0 1.6479596224019004" />
     <axis xyz="1 0 0"/>
       <limit effort="0.0" lower="-3.14159" upper="3.14159" velocity="0.0"/>
    </joint>
    <link name="k0">
        <inertial>
            <origin xyz="0.23912793841878088 0.20962637660175754 0.12429648138020691" rpy="0 0 0"/>
            <mass value="1" />
            <inertia ixx="100" ixy="0" ixz="0" iyy="100" iyz="0" izz="100" />
        </inertial>
        <visual>
            <origin xyz="0.23912793841878088 0.20962637660175754 0.12429648138020691" rpy="0 0 0"/>
            <geometry>
                <box size="0.47825587683756177 0.41925275320351507 0.24859296276041382" />
            </geometry>
            <material name="Cyan">
                <color rgba="0 1.0 1.0 1.0"/>
            </material>
        </visual>
        <collision>
            <origin xyz="0.23912793841878088 0.20962637660175754 0.12429648138020691" rpy="0 0 0"/>
            <geometry>
                <box size="0.47825587683756177 0.41925275320351507 0.24859296276041382" />
            </geometry>
        </collision>
    </link>
    <joint name="k0_k1" type="revolute">
       <parent link="k0"/>
       <child  link="k1"/>
       <origin rpy="1 0 0" xyz="0 0 0.24859296276041382" />
     <axis xyz="1 0 0"/>
       <limit effort="0.0" lower="-3.14159" upper="3.14159" velocity="0.0"/>
    </joint>
    <link name="k1">
        <inertial>
            <origin xyz="0.21666618408958752 0.3670712039200229 0.4553710163190997" rpy="0 0 0"/>
            <mass value="1" />
            <inertia ixx="100" ixy="0" ixz="0" iyy="100" iyz="0" izz="100" />
        </inertial>
        <visual>
            <origin xyz="0.21666618408958752 0.3670712039200229 0.4553710163190997" rpy="0 0 0"/>
            <geometry>
                <box size="0.43333236817917503 0.7341424078400458 0.9107420326381994" />
            </geometry>
            <material name="Green">
                <color rgba="0 1.0 0.0 1.0"/>
            </material>
        </visual>
        <collision>
            <origin xyz="0.21666618408958752 0.3670712039200229 0.4553710163190997" rpy="0 0 0"/>
            <geometry>
                <box size="0.43333236817917503 0.7341424078400458 0.9107420326381994" />
            </geometry>
        </collision>
    </link>
</robot>